Workbook

Sheet README
A1: Random versus spatial cross-validation in machine-learning environmental maps: database of the systematic review and meta-analysis
A2: Vilca-Solorzano, R.A. & Torres-Cruz, F. Universidad Nacional del Altiplano, Puno, Peru. Data: https://doi.org/10.17605/OSF.IO/S8Y5H · Protocol: https://doi.org/10.17605/OSF.IO/6P8YM
A4: Sheet | B4: Type | C4: Content
A5: S1_Validation_practice | B5: Summary | C5: Summary tables (formulas): validation schemes, folds, splits, block-size choice, sampling design, data source.
A6: S2_Countries | B6: Summary | C6: Summary table (formulas): studies per country and continent, ranked.
A7: S3_When_to_use | B7: Summary | C7: Summary table (linked formulas): size of the gap per situation and which validation to use.
A8: 1_Screening | B8: Raw | C8: All 3,227 records screened on title and abstract, with decision and reason (raw).
A9: 2_Full_text | B9: Raw | C9: 390 full texts assessed (+2 not retrieved): include (266) or exclude with reason E1-E6 (raw).
A10: 3_Extraction_raw | B10: Raw | C10: Every extracted row (model x metric x data set) of the included studies, values as reported (raw).
A11: 4_Studies | B11: Raw | C11: One row per included study (266): country, data source, sampling design and validation schemes (raw, second pass).
A12: 5_Effect_sizes | B12: Processed | C12: Effect sizes used in the meta-analysis (processed): yi = random minus spatial (lnRR for RMSE), vi = sampling variance.
A13: 6_Pooled | B13: Processed | C13: Pooled three-level random-effects estimates per metric, with sensitivity analyses (processed).
A14: 7_Moderators | B14: Processed | C14: Subgroup estimates by sampling design, model, domain and spatial-CV type (processed).
A15: 8_Study_moderators | B15: Processed | C15: Subgroup estimates by study-level variables: data source, random-CV scheme, block-size justification, n, continent (processed).
... A20: 12_Risk_of_bias | B20: Processed | C20: Risk-of-bias and reporting items per study (PROBAST-based).
A22: Codes. yi > 0 means random cross-validation gave the more favourable value. lnRR = ln(RMSE spatial / RMSE random); % higher = 100*(exp(lnRR)-1).
A23: sampling_h: clustered, regular_grid, probability_random, unknown (not reported). Rows in 3_Extraction_raw with primary = yes were analysed.
A24: Raw sheets are as extracted; processed sheets are outputs of analysis/01, 04 and 07 (R, metafor). Summary sheets use COUNTIF/INDEX formulas and update when the data change.
A25: Abstracts and full texts are not included (copyright).

Sheet S1_Validation_practice
A1: Which validation designs are used, and on what data (counts recalculate from sheet 4_Studies)
A3: Random cross-validation used as baseline
A4: Level | B4: Studies | C4: % of 266
A5: k-fold | B5: =COUNTIF('4_Studies'!$U$2:$U$267,"kfold") -> 115 | C5: =B5/COUNTA('4_Studies'!$A$2:$A$267) -> 0.43233083
A6: Repeated k-fold | B6: =COUNTIF('4_Studies'!$U$2:$U$267,"repeated_kfold") -> 27 | C6: =B6/COUNTA('4_Studies'!$A$2:$A$267) -> 0.10150376
A7: Nested k-fold | B7: =COUNTIF('4_Studies'!$U$2:$U$267,"nested_kfold") -> 7 | C7: =B7/COUNTA('4_Studies'!$A$2:$A$267) -> 0.026315789
A8: Hold-out split | B8: =COUNTIF('4_Studies'!$U$2:$U$267,"holdout_split") -> 103 | C8: =B8/COUNTA('4_Studies'!$A$2:$A$267) -> 0.38721805
A9: Leave-one-out | B9: =COUNTIF('4_Studies'!$U$2:$U$267,"LOO") -> 6 | C9: =B9/COUNTA('4_Studies'!$A$2:$A$267) -> 0.022556391
A10: Out-of-bag | B10: =COUNTIF('4_Studies'!$U$2:$U$267,"OOB") -> 6 | C10: =B10/COUNTA('4_Studies'!$A$2:$A$267) -> 0.022556391
A11: Other | B11: =COUNTIF('4_Studies'!$U$2:$U$267,"other") -> 2 | C11: =B11/COUNTA('4_Studies'!$A$2:$A$267) -> 0.007518797
A13: Number of folds (k-fold studies)
A14: Level | B14: Studies | C14: % of 266
A15: 5-fold | B15: =COUNTIF('4_Studies'!$V$2:$V$267,"5") -> 64 | C15: =B15/COUNTA('4_Studies'!$A$2:$A$267) -> 0.2406015
A16: 10-fold | B16: =COUNTIF('4_Studies'!$V$2:$V$267,"10") -> 71 | C16: =B16/COUNTA('4_Studies'!$A$2:$A$267) -> 0.26691729
A17: 4-fold | B17: =COUNTIF('4_Studies'!$V$2:$V$267,"4") -> 4 | C17: =B17/COUNTA('4_Studies'!$A$2:$A$267) -> 0.015037594
A18: 15-fold | B18: =COUNTIF('4_Studies'!$V$2:$V$267,"15") -> 3 | C18: =B18/COUNTA('4_Studies'!$A$2:$A$267) -> 0.011278195
A20: Hold-out split (training %)
A21: Level | B21: Studies | C21: % of 266
A22: 80/20 | B22: =COUNTIF('4_Studies'!$X$2:$X$267,"80") -> 42 | C22: =B22/COUNTA('4_Studies'!$A$2:$A$267) -> 0.15789474
A23: 70/30 | B23: =COUNTIF('4_Studies'!$X$2:$X$267,"70") -> 41 | C23: =B23/COUNTA('4_Studies'!$A$2:$A$267) -> 0.15413534
A24: 75/25 | B24: =COUNTIF('4_Studies'!$X$2:$X$267,"75") -> 13 | C24: =B24/COUNTA('4_Studies'!$A$2:$A$267) -> 0.04887218
A25: 60/40 | B25: =COUNTIF('4_Studies'!$X$2:$X$267,"60") -> 11 | C25: =B25/COUNTA('4_Studies'!$A$2:$A$267) -> 0.041353383
A26: 90/10 | B26: =COUNTIF('4_Studies'!$X$2:$X$267,"90") -> 4 | C26: =B26/COUNTA('4_Studies'!$A$2:$A$267) -> 0.015037594
A28: Stratified random folds
A29: Level | B29: Studies | C29: % of 266
A30: yes | B30: =COUNTIF('4_Studies'!$Z$2:$Z$267,"yes") -> 56 | C30: =B30/COUNTA('4_Studies'!$A$2:$A$267) -> 0.21052632
A31: no | B31: =COUNTIF('4_Studies'!$Z$2:$Z$267,"no") -> 158 | C31: =B31/COUNTA('4_Studies'!$A$2:$A$267) -> 0.59398496
A33: Spatial cross-validation used
A34: Level | B34: Studies | C34: % of 266
A35: Leave-location-out | B35: =COUNTIF('4_Studies'!$AA$2:$AA$267,"leave_location_out") -> 111 | C35: =B35/COUNTA('4_Studies'!$A$2:$A$267) -> 0.41729323
A36: Spatial blocks | B36: =COUNTIF('4_Studies'!$AA$2:$AA$267,"blocks") -> 79 | C36: =B36/COUNTA('4_Studies'!$A$2:$A$267) -> 0.29699248
A37: k-means clusters | B37: =COUNTIF('4_Studies'!$AA$2:$AA$267,"kmeans_clusters") -> 39 | C37: =B37/COUNTA('4_Studies'!$A$2:$A$267) -> 0.14661654
A38: Buffered leave-one-out | B38: =COUNTIF('4_Studies'!$AA$2:$AA$267,"buffered_LOO") -> 10 | C38: =B38/COUNTA('4_Studies'!$A$2:$A$267) -> 0.037593985
A39: NNDM / kNNDM | B39: =COUNTIF('4_Studies'!$AA$2:$AA$267,"NNDM_kNNDM") -> 3 | C39: =B39/COUNTA('4_Studies'!$A$2:$A$267) -> 0.011278195
A40: Other | B40: =COUNTIF('4_Studies'!$AA$2:$AA$267,"other") -> 24 | C40: =B40/COUNTA('4_Studies'!$A$2:$A$267) -> 0.090225564
A42: How the block or buffer size was chosen
A43: Level | B43: Studies | C43: % of 266
A44: From the autocorrelation range | B44: =COUNTIF('4_Studies'!$AE$2:$AE$267,"autocorrelation_range") -> 26 | C44: =B44/COUNTA('4_Studies'!$A$2:$A$267) -> 0.097744361
A45: Expert choice | B45: =COUNTIF('4_Studies'!$AE$2:$AE$267,"expert_choice") -> 63 | C45: =B45/COUNTA('4_Studies'!$A$2:$A$267) -> 0.23684211
A46: Not justified | B46: =COUNTIF('4_Studies'!$AE$2:$AE$267,"not_justified") -> 154 | C46: =B46/COUNTA('4_Studies'!$A$2:$A$267) -> 0.57894737
...

Sheet S2_Countries
A1: Where the studies were carried out (counts recalculate from sheet 4_Studies; multi-country studies count once per country)
A3: Rank | B3: ISO3 | C3: Country | D3: Continent | E3: Studies | F3: % of 266
A4: =RANK(E4,$E$4:$E$89) -> 1 | B4: CHN | C4: China | D4: Asia | E4: =COUNTIF('4_Studies'!$F$2:$F$267,"*CHN*") -> 54 | F4: =E4/COUNTA('4_Studies'!$A$2:$A$267) -> 0.20300752
A5: =RANK(E5,$E$4:$E$89) -> 2 | B5: USA | C5: United States | D5: North America | E5: =COUNTIF('4_Studies'!$F$2:$F$267,"*USA*") -> 42 | F5: =E5/COUNTA('4_Studies'!$A$2:$A$267) -> 0.15789474
A6: =RANK(E6,$E$4:$E$89) -> 3 | B6: CAN | C6: Canada | D6: North America | E6: =COUNTIF('4_Studies'!$F$2:$F$267,"*CAN*") -> 12 | F6: =E6/COUNTA('4_Studies'!$A$2:$A$267) -> 0.045112782
A7: =RANK(E7,$E$4:$E$89) -> 3 | B7: DEU | C7: Germany | D7: Europe | E7: =COUNTIF('4_Studies'!$F$2:$F$267,"*DEU*") -> 12 | F7: =E7/COUNTA('4_Studies'!$A$2:$A$267) -> 0.045112782
A8: =RANK(E8,$E$4:$E$89) -> 5 | B8: AUS | C8: Australia | D8: Oceania | E8: =COUNTIF('4_Studies'!$F$2:$F$267,"*AUS*") -> 11 | F8: =E8/COUNTA('4_Studies'!$A$2:$A$267) -> 0.041353383
A9: =RANK(E9,$E$4:$E$89) -> 5 | B9: BRA | C9: Brazil | D9: South America | E9: =COUNTIF('4_Studies'!$F$2:$F$267,"*BRA*") -> 11 | F9: =E9/COUNTA('4_Studies'!$A$2:$A$267) -> 0.041353383
A10: =RANK(E10,$E$4:$E$89) -> 7 | B10: ESP | C10: Spain | D10: Europe | E10: =COUNTIF('4_Studies'!$F$2:$F$267,"*ESP*") -> 10 | F10: =E10/COUNTA('4_Studies'!$A$2:$A$267) -> 0.037593985
A11: =RANK(E11,$E$4:$E$89) -> 8 | B11: FRA | C11: France | D11: Europe | E11: =COUNTIF('4_Studies'!$F$2:$F$267,"*FRA*") -> 8 | F11: =E11/COUNTA('4_Studies'!$A$2:$A$267) -> 0.030075188
A12: =RANK(E12,$E$4:$E$89) -> 9 | B12: IND | C12: India | D12: Asia | E12: =COUNTIF('4_Studies'!$F$2:$F$267,"*IND*") -> 5 | F12: =E12/COUNTA('4_Studies'!$A$2:$A$267) -> 0.018796992
A13: =RANK(E13,$E$4:$E$89) -> 9 | B13: PER | C13: Peru | D13: South America | E13: =COUNTIF('4_Studies'!$F$2:$F$267,"*PER*") -> 5 | F13: =E13/COUNTA('4_Studies'!$A$2:$A$267) -> 0.018796992
A14: =RANK(E14,$E$4:$E$89) -> 11 | B14: AUT | C14: Austria | D14: Europe | E14: =COUNTIF('4_Studies'!$F$2:$F$267,"*AUT*") -> 4 | F14: =E14/COUNTA('4_Studies'!$A$2:$A$267) -> 0.015037594
A15: =RANK(E15,$E$4:$E$89) -> 11 | B15: IDN | C15: Indonesia | D15: Asia | E15: =COUNTIF('4_Studies'!$F$2:$F$267,"*IDN*") -> 4 | F15: =E15/COUNTA('4_Studies'!$A$2:$A$267) -> 0.015037594
A16: =RANK(E16,$E$4:$E$89) -> 11 | B16: JPN | C16: Japan | D16: Asia | E16: =COUNTIF('4_Studies'!$F$2:$F$267,"*JPN*") -> 4 | F16: =E16/COUNTA('4_Studies'!$A$2:$A$267) -> 0.015037594
A17: =RANK(E17,$E$4:$E$89) -> 11 | B17: TWN | C17: Taiwan | D17: Asia | E17: =COUNTIF('4_Studies'!$F$2:$F$267,"*TWN*") -> 4 | F17: =E17/COUNTA('4_Studies'!$A$2:$A$267) -> 0.015037594
A18: =RANK(E18,$E$4:$E$89) -> 11 | B18: VNM | C18: Vietnam | D18: Asia | E18: =COUNTIF('4_Studies'!$F$2:$F$267,"*VNM*") -> 4 | F18: =E18/COUNTA('4_Studies'!$A$2:$A$267) -> 0.015037594
A19: =RANK(E19,$E$4:$E$89) -> 16 | B19: BFA | C19: Burkina Faso | D19: Africa | E19: =COUNTIF('4_Studies'!$F$2:$F$267,"*BFA*") -> 3 | F19: =E19/COUNTA('4_Studies'!$A$2:$A$267) -> 0.011278195
A20: =RANK(E20,$E$4:$E$89) -> 16 | B20: ETH | C20: Ethiopia | D20: Africa | E20: =COUNTIF('4_Studies'!$F$2:$F$267,"*ETH*") -> 3 | F20: =E20/COUNTA('4_Studies'!$A$2:$A$267) -> 0.011278195
A21: =RANK(E21,$E$4:$E$89) -> 16 | B21: GBR | C21: United Kingdom | D21: Europe | E21: =COUNTIF('4_Studies'!$F$2:$F$267,"*GBR*") -> 3 | F21: =E21/COUNTA('4_Studies'!$A$2:$A$267) -> 0.011278195
A22: =RANK(E22,$E$4:$E$89) -> 16 | B22: ITA | C22: Italy | D22: Europe | E22: =COUNTIF('4_Studies'!$F$2:$F$267,"*ITA*") -> 3 | F22: =E22/COUNTA('4_Studies'!$A$2:$A$267) -> 0.011278195
A23: =RANK(E23,$E$4:$E$89) -> 16 | B23: KOR | C23: South Korea | D23: Asia | E23: =COUNTIF('4_Studies'!$F$2:$F$267,"*KOR*") -> 3 | F23: =E23/COUNTA('4_Studies'!$A$2:$A$267) -> 0.011278195
A24: =RANK(E24,$E$4:$E$89) -> 16 | B24: MAR | C24: Morocco | D24: Africa | E24: =COUNTIF('4_Studies'!$F$2:$F$267,"*MAR*") -> 3 | F24: =E24/COUNTA('4_Studies'!$A$2:$A$267) -> 0.011278195
A25: =RANK(E25,$E$4:$E$89) -> 16 | B25: NLD | C25: Netherlands | D25: Europe | E25: =COUNTIF('4_Studies'!$F$2:$F$267,"*NLD*") -> 3 | F25: =E25/COUNTA('4_Studies'!$A$2:$A$267) -> 0.011278195
A26: =RANK(E26,$E$4:$E$89) -> 16 | B26: PRT | C26: Portugal | D26: Europe | E26: =COUNTIF('4_Studies'!$F$2:$F$267,"*PRT*") -> 3 | F26: =E26/COUNTA('4_Studies'!$A$2:$A$267) -> 0.011278195
A27: =RANK(E27,$E$4:$E$89) -> 16 | B27: SWE | C27: Sweden | D27: Europe | E27: =COUNTIF('4_Studies'!$F$2:$F$267,"*SWE*") -> 3 | F27: =E27/COUNTA('4_Studies'!$A$2:$A$267) -> 0.011278195
A28: =RANK(E28,$E$4:$E$89) -> 16 | B28: THA | C28: Thailand | D28: Asia | E28: =COUNTIF('4_Studies'!$F$2:$F$267,"*THA*") -> 3 | F28: =E28/COUNTA('4_Studies'!$A$2:$A$267) -> 0.011278195
A29: =RANK(E29,$E$4:$E$89) -> 26 | B29: ARG | C29: Argentina | D29: South America | E29: =COUNTIF('4_Studies'!$F$2:$F$267,"*ARG*") -> 2 | F29: =E29/COUNTA('4_Studies'!$A$2:$A$267) -> 0.007518797
A30: =RANK(E30,$E$4:$E$89) -> 26 | B30: ATA | C30: Antarctica | D30: Antarctica | E30: =COUNTIF('4_Studies'!$F$2:$F$267,"*ATA*") -> 2 | F30: =E30/COUNTA('4_Studies'!$A$2:$A$267) -> 0.007518797
A31: =RANK(E31,$E$4:$E$89) -> 26 | B31: BGR | C31: Bulgaria | D31: Europe | E31: =COUNTIF('4_Studies'!$F$2:$F$267,"*BGR*") -> 2 | F31: =E31/COUNTA('4_Studies'!$A$2:$A$267) -> 0.007518797
A32: =RANK(E32,$E$4:$E$89) -> 26 | B32: BOL | C32: Bolivia | D32: South America | E32: =COUNTIF('4_Studies'!$F$2:$F$267,"*BOL*") -> 2 | F32: =E32/COUNTA('4_Studies'!$A$2:$A$267) -> 0.007518797
A33: =RANK(E33,$E$4:$E$89) -> 26 | B33: CHE | C33: Switzerland | D33: Europe | E33: =COUNTIF('4_Studies'!$F$2:$F$267,"*CHE*") -> 2 | F33: =E33/COUNTA('4_Studies'!$A$2:$A$267) -> 0.007518797
A34: =RANK(E34,$E$4:$E$89) -> 26 | B34: CHL | C34: Chile | D34: South America | E34: =COUNTIF('4_Studies'!$F$2:$F$267,"*CHL*") -> 2 | F34: =E34/COUNTA('4_Studies'!$A$2:$A$267) -> 0.007518797
A35: =RANK(E35,$E$4:$E$89) -> 26 | B35: CMR | C35: Cameroon | D35: Africa | E35: =COUNTIF('4_Studies'!$F$2:$F$267,"*CMR*") -> 2 | F35: =E35/COUNTA('4_Studies'!$A$2:$A$267) -> 0.007518797
A36: =RANK(E36,$E$4:$E$89) -> 26 | B36: CZE | C36: Czechia | D36: Europe | E36: =COUNTIF('4_Studies'!$F$2:$F$267,"*CZE*") -> 2 | F36: =E36/COUNTA('4_Studies'!$A$2:$A$267) -> 0.007518797
A37: =RANK(E37,$E$4:$E$89) -> 26 | B37: DNK | C37: Denmark | D37: Europe | E37: =COUNTIF('4_Studies'!$F$2:$F$267,"*DNK*") -> 2 | F37: =E37/COUNTA('4_Studies'!$A$2:$A$267) -> 0.007518797
A38: =RANK(E38,$E$4:$E$89) -> 26 | B38: ECU | C38: Ecuador | D38: South America | E38: =COUNTIF('4_Studies'!$F$2:$F$267,"*ECU*") -> 2 | F38: =E38/COUNTA('4_Studies'!$A$2:$A$267) -> 0.007518797
A39: =RANK(E39,$E$4:$E$89) -> 26 | B39: EGY | C39: Egypt | D39: Africa | E39: =COUNTIF('4_Studies'!$F$2:$F$267,"*EGY*") -> 2 | F39: =E39/COUNTA('4_Studies'!$A$2:$A$267) -> 0.007518797
A40: =RANK(E40,$E$4:$E$89) -> 26 | B40: GHA | C40: Ghana | D40: Africa | E40: =COUNTIF('4_Studies'!$F$2:$F$267,"*GHA*") -> 2 | F40: =E40/COUNTA('4_Studies'!$A$2:$A$267) -> 0.007518797
A41: =RANK(E41,$E$4:$E$89) -> 26 | B41: HRV | C41: Croatia | D41: Europe | E41: =COUNTIF('4_Studies'!$F$2:$F$267,"*HRV*") -> 2 | F41: =E41/COUNTA('4_Studies'!$A$2:$A$267) -> 0.007518797
...

Sheet S3_When_to_use
A1: How large is the gap, and which validation to use (values linked to sheets 6, 7, 8 and 9)
A3: Situation | B3: R2 random minus spatial | C3: RMSE higher under spatial (%) | D3: Studies (R2) | E3: What to do
A4: All studies (pooled) | B4: ='6_Pooled'!D2 -> 0.20871274 | C4: =100*(EXP('6_Pooled'!D3)-1) -> 30.290372 | D4: ='6_Pooled'!C2 -> 132 | E4: Expect random CV to look better; report both designs.
A5: Clustered sample (roads, stations, plots) | B5: =INDEX('7_Moderators'!$E:$E,MATCH("dR2|sampling_h|clustered",'7_Moderators'!$A:$A,0)) -> 0.2359642 | C5: =100*(EXP(INDEX('7_Moderators'!$E:$E,MATCH("lnRR_RMSE|sampling_h|clustered",'7_Moderators'!$A:$A,0)))-1) -> 39.527077 | D5: =INDEX('7_Moderators'!$I:$I,MATCH("dR2|sampling_h|clustered",'7_Moderators'!$A:$A,0)) -> 77 | E5: Use spatial CV (blocks at least as wide as the autocorrelation range, or kNNDM); random CV is an upper bound.
A6: Regular grid | B6: =INDEX('7_Moderators'!$E:$E,MATCH("dR2|sampling_h|regular_grid",'7_Moderators'!$A:$A,0)) -> 0.22020918 | C6: =100*(EXP(INDEX('7_Moderators'!$E:$E,MATCH("lnRR_RMSE|sampling_h|regular_grid",'7_Moderators'!$A:$A,0)))-1) -> 16.851216 | D6: =INDEX('7_Moderators'!$I:$I,MATCH("dR2|sampling_h|regular_grid",'7_Moderators'!$A:$A,0)) -> 22 | E6: Report both; a moderate gap is expected.
A7: Sampling design not reported | B7: =INDEX('7_Moderators'!$E:$E,MATCH("dR2|sampling_h|unknown",'7_Moderators'!$A:$A,0)) -> 0.15578201 | C7: =100*(EXP(INDEX('7_Moderators'!$E:$E,MATCH("lnRR_RMSE|sampling_h|unknown",'7_Moderators'!$A:$A,0)))-1) -> 18.085275 | D7: =INDEX('7_Moderators'!$I:$I,MATCH("dR2|sampling_h|unknown",'7_Moderators'!$A:$A,0)) -> 30 | E7: Treat as clustered; describe how the data were collected.
A8: Probability sample of the mapped area | B8: =INDEX('7_Moderators'!$E:$E,MATCH("dR2|sampling_h|probability_random",'7_Moderators'!$A:$A,0)) -> 0.11619072 | C8: =100*(EXP(INDEX('7_Moderators'!$E:$E,MATCH("lnRR_RMSE|sampling_h|probability_random",'7_Moderators'!$A:$A,0)))-1) -> 11.83939 | D8: =INDEX('7_Moderators'!$I:$I,MATCH("dR2|sampling_h|probability_random",'7_Moderators'!$A:$A,0)) -> 9 | E8: Random CV is adequate for the accuracy of the whole map.
A9: Block size from the autocorrelation range | B9: =INDEX('8_Study_moderators'!$E:$E,MATCH("dR2|Block size justified by|autocorrelation_range",'8_Study_moderators'!$A:$A,0)) -> 0.40207396 | D9: =INDEX('8_Study_moderators'!$H:$H,MATCH("dR2|Block size justified by|autocorrelation_range",'8_Study_moderators'!$A:$A,0)) -> 9 | E9: Size blocks from the semivariogram range; the gap measured is then about 2.7 times larger.
A10: Block size not justified | B10: =INDEX('8_Study_moderators'!$E:$E,MATCH("dR2|Block size justified by|not_justified",'8_Study_moderators'!$A:$A,0)) -> 0.15149789 | D10: =INDEX('8_Study_moderators'!$H:$H,MATCH("dR2|Block size justified by|not_justified",'8_Study_moderators'!$A:$A,0)) -> 74 | E10: Gap is underestimated; justify the block size.
A11: Random baseline: leave-one-out / out-of-bag | B11: =INDEX('8_Study_moderators'!$E:$E,MATCH("dR2|Random-CV scheme|LOO/OOB",'8_Study_moderators'!$A:$A,0)) -> 0.38458686 | D11: =INDEX('8_Study_moderators'!$H:$H,MATCH("dR2|Random-CV scheme|LOO/OOB",'8_Study_moderators'!$A:$A,0)) -> 7 | E11: Most optimistic baseline; avoid as the reference.
A12: Random baseline: k-fold | B12: =INDEX('8_Study_moderators'!$E:$E,MATCH("dR2|Random-CV scheme|k-fold",'8_Study_moderators'!$A:$A,0)) -> 0.18351087 | D12: =INDEX('8_Study_moderators'!$H:$H,MATCH("dR2|Random-CV scheme|k-fold",'8_Study_moderators'!$A:$A,0)) -> 77 | E12: 5 or 10 folds give the same gap.
A13: Random baseline: hold-out split | B13: =INDEX('8_Study_moderators'!$E:$E,MATCH("dR2|Random-CV scheme|Hold-out split",'8_Study_moderators'!$A:$A,0)) -> 0.22719243 | D13: =INDEX('8_Study_moderators'!$H:$H,MATCH("dR2|Random-CV scheme|Hold-out split",'8_Study_moderators'!$A:$A,0)) -> 47 | E13: 70/30 and 80/20 give the same gap.
A15: Agreement with independent test data
A16: Quantity | B16: Mean | C16: 95% CI low | D16: 95% CI high | E16: p
A17: Optimism of random CV (R2, AUC, accuracy) | B17: ='11_Independent_summary'!C2 -> 0.15481129 | C17: ='11_Independent_summary'!D2 -> 0.073765741 | D17: ='11_Independent_summary'!E2 -> 0.23585684 | E17: ='11_Independent_summary'!F2 -> 0.00328981
A18: Optimism of spatial CV (R2, AUC, accuracy) | B18: ='11_Independent_summary'!C3 -> 0.025712903 | C18: ='11_Independent_summary'!D3 -> -0.03710933 | D18: ='11_Independent_summary'!E3 -> 0.088535137 | E18: ='11_Independent_summary'!F3 -> 0.35710749
A19: Share of comparisons where spatial CV was closer | B19: ='11_Independent_summary'!C5 -> 0.72580645
A21: Positive optimism: cross-validation estimate better than the independent test. Values recalculate if sheets 6-11 are updated.

Sheet 1_Screening
A1: record_id | B1: priority | C1: source_query | D1: Year | E1: Title | F1: Source title | G1: DOI | H1: EID | I1: ta_decision | J1: ta_reason
A2: R0001 | B2: A_both | C2: v1/v2 | D2: 2020 | E2: Spatial validation reveals poor predictive performance of large-scale ecological mapping models | F2: Nature Communications | G2: 10.1038/s41467-020-18321-y | H2: 2-s2.0-85090794111 | I2: include
A3: R0002 | B3: A_both | C3: v1/v2 | D3: 2019 | E3: Hyperparameter tuning and performance assessment of statistical and machine-learning algorithms using spatial data | F3: Ecological Modelling | G3: 10.1016/j.ecolmodel.2019.06.002 | H3: 2-s2.0-85067413523 | I3: include
A4: R0003 | B4: A_both | C4: v1/v2 | D4: 2018 | E4: Improving performance of spatio-temporal machine learning models using forward feature selection and target-oriented validation | F4: Environmental Modelling and Software | G4: 10.1016/j.envsoft.2017.12.001 | H4: 2-s2.0-85038035153 | I4: include
A5: R0004 | B5: A_both | C5: v1/v2 | D5: 2020 | E5: Testing whether ensemble modelling is advantageous for maximising predictive performance of species distribution models | F5: Ecography | G5: 10.1111/ecog.04890 | H5: 2-s2.0-85078760878 | I5: include
A6: R0005 | B6: A_both | C6: v1/v2 | D6: 2019 | E6: Importance of spatial predictor variable selection in machine learning applications – Moving from data reproduction to spatial prediction | F6: Ecological Modelling | G6: 10.1016/j.ecolmodel.2019.108815 | H6: 2-s2.0-85072071754 | I6: include
A7: R0006 | B7: A_both | C7: v1/v2 | D7: 2021 | E7: Assessing the reliability of species distribution projections in climate change research | F7: Diversity and Distributions | G7: 10.1111/ddi.13252 | H7: 2-s2.0-85101122718 | I7: include
A8: R0007 | B8: A_both | C8: v1/v2 | D8: 2021 | E8: Spatial cross-validation is not the right way to evaluate map accuracy | F8: Ecological Modelling | G8: 10.1016/j.ecolmodel.2021.109692 | H8: 2-s2.0-85112366164 | I8: include
A9: R0008 | B9: A_both | C9: v1/v2 | D9: 2020 | E9: Comparison of Machine Learning and Land Use Regression for fine scale spatiotemporal estimation of ambient air pollution: Modeling ozone concentrations across the contiguous United States | F9: Environment International | G9: 10.1016/j.envint.2020.105827 | H9: 2-s2.0-85086853689 | I9: maybe
A10: R0009 | B10: A_both | C10: v1/v2 | D10: 2022 | E10: Spatially autocorrelated training and validation samples inflate performance assessment of convolutional neural networks | F10: ISPRS Open Journal of Photogrammetry and Remote Sensing | G10: 10.1016/j.ophoto.2022.100018 | H10: 2-s2.0-85135896909 | I10: include
A11: R0010 | B11: A_both | C11: v1/v2 | D11: 2022 | E11: Fair train-test split in machine learning: Mitigating spatial autocorrelation for improved prediction accuracy | F11: Journal of Petroleum Science and Engineering | G11: 10.1016/j.petrol.2021.109885 | H11: 2-s2.0-85119406427 | I11: exclude | J11: E4
A12: R0011 | B12: A_both | C12: v1/v2 | D12: 2022 | E12: Nearest neighbour distance matching Leave-One-Out Cross-Validation for map validation | F12: Methods in Ecology and Evolution | G12: 10.1111/2041-210X.13851 | H12: 2-s2.0-85127570689 | I12: include
A13: R0012 | B13: A_both | C13: v1/v2 | D13: 2022 | E13: Dealing with clustered samples for assessing map accuracy by cross-validation | F13: Ecological Informatics | G13: 10.1016/j.ecoinf.2022.101665 | H13: 2-s2.0-85129503131 | I13: include
A14: R0013 | B14: A_both | C14: v1/v2 | D14: 2021 | E14: Global Prediction of Soil Saturated Hydraulic Conductivity Using Random Forest in a Covariate-Based GeoTransfer Function (CoGTF) Framework | F14: Journal of Advances in Modeling Earth Systems | G14: 10.1029/2020MS002242 | H14: 2-s2.0-85104950878 | I14: include
A15: R0014 | B15: A_both | C15: v1/v2 | D15: 2024 | E15: Corn Grain Yield Prediction Using UAV-Based High Spatiotemporal Resolution Imagery, Machine Learning, and Spatial Cross-Validation | F15: Remote Sensing | G15: 10.3390/rs16040683 | H15: 2-s2.0-85185711225 | I15: include
A16: R0015 | B16: A_both | C16: v1/v2 | D16: 2024 | E16: Random forest and spatial cross-validation performance in predicting species abundance distributions | F16: Environmental Systems Research | G16: 10.1186/s40068-024-00352-9 | H16: 2-s2.0-85197278197 | I16: include
A17: R0016 | B17: A_both | C17: v1/v2 | D17: 2025 | E17: Random Cross-Validation Produces Biased Assessment of Machine Learning Performance in Regional Landslide Susceptibility Prediction | F17: Remote Sensing | G17: 10.3390/rs17020213 | H17: 2-s2.0-85215798869 | I17: include
A18: R0017 | B18: A_both | C18: v1/v2 | D18: 2019 | E18: A spatially explicit comparison of quantitative and categorical modelling approaches for mapping seabed sediments using random forest | F18: Geosciences (Switzerland) | G18: 10.3390/geosciences9060254 | H18: 2-s2.0-85067996135 | I18: include
A19: R0018 | B19: A_both | C19: v1/v2 | D19: 2025 | E19: Choosing blocks for spatial cross-validation: lessons from a marine remote sensing case study | F19: Frontiers in Remote Sensing | G19: 10.3389/frsen.2025.1531097 | H19: 2-s2.0-105001675641 | I19: maybe
A20: R0019 | B20: A_both | C20: v1/v2 | D20: 2023 | E20: Examining the Spatially Varying Relationships between Landslide Susceptibility and Conditioning Factors Using a Geographical Random Forest Approach: A Case Study in Liangshan, China | F20: Remote Sensing | G20: 10.3390/rs15061513 | H20: 2-s2.0-85151976377 | I20: maybe
A21: R0020 | B21: A_both | C21: v1/v2 | D21: 2022 | E21: Predicting methane emission in Canadian Holstein dairy cattle using milk mid-infrared reflectance spectroscopy and other commonly available predictors via artificial neural networks | F21: Journal of Dairy Science | G21: 10.3168/jds.2021-21176 | H21: 2-s2.0-85137018329 | I21: exclude | J21: E4
A22: R0021 | B22: A_both | C22: v1/v2 | D22: 2018 | E22: Fire regimes at the arid fringe: A 16-year remote sensing perspective (2000–2016) on the controls of fire activity in Namibia from spatial predictive models | F22: Ecological Indicators | G22: 10.1016/j.ecolind.2018.04.022 | H22: 2-s2.0-85045706551 | I22: include
A23: R0022 | B23: A_both | C23: v1/v2 | D23: 2019 | E23: Broad-scale species distribution models applied to data-poor areas | F23: Progress in Oceanography | G23: 10.1016/j.pocean.2019.04.007 | H23: 2-s2.0-85065068292 | I23: include
A24: R0023 | B24: A_both | C24: v1/v2 | D24: 2023 | E24: Evaluation of computer vision for detecting agonistic behavior of pigs in a single-space feeding stall through blocked cross-validation strategies | F24: Computers and Electronics in Agriculture | G24: 10.1016/j.compag.2022.107520 | H24: 2-s2.0-85144014809 | I24: exclude | J24: E4
A25: R0024 | B25: A_both | C25: v1/v2 | D25: 2024 | E25: Improving spatial transferability of deep learning models for small-field crop yield prediction | F25: ISPRS Open Journal of Photogrammetry and Remote Sensing | G25: 10.1016/j.ophoto.2024.100064 | H25: 2-s2.0-85191008945 | I25: include
A26: R0025 | B26: A_both | C26: v1/v2 | D26: 2022 | E26: Assessing spatial transferability of a random forest metamodel for predicting drainage fraction | F26: Journal of Hydrology | G26: 10.1016/j.jhydrol.2022.128177 | H26: 2-s2.0-85134575492 | I26: include
A27: R0026 | B27: A_both | C27: v1/v2 | D27: 2021 | E27: Estimation and mapping of surface soil properties in the Caucasus Mountains, Azerbaijan using high-resolution remote sensing data | F27: Geoderma Regional | G27: 10.1016/j.geodrs.2021.e00411 | H27: 2-s2.0-85108591332 | I27: exclude | J27: E2
A28: R0027 | B28: A_both | C28: v1/v2 | D28: 2022 | E28: Spatiotemporal distribution of labeled data can bias the validation and selection of supervised learning algorithms: A marine remote sensing example | F28: ISPRS Journal of Photogrammetry and Remote Sensing | G28: 10.1016/j.isprsjprs.2022.02.023 | H28: 2-s2.0-85125871380 | I28: include
A29: R0028 | B29: A_both | C29: v1/v2 | D29: 2022 | E29: Identifying low-PM2.5 exposure commuting routes for cyclists through modeling with the random forest algorithm based on low-cost sensor measurements in three Asian cities | F29: Environmental Pollution | G29: 10.1016/j.envpol.2021.118597 | H29: 2-s2.0-85120416457 | I29: include
A30: R0029 | B30: A_both | C30: v1/v2 | D30: 2024 | E30: Cross-validation strategy for performance evaluation of machine learning algorithms in underwater acoustic target recognition | F30: Ocean Engineering | G30: 10.1016/j.oceaneng.2024.117236 | H30: 2-s2.0-85186371520 | I30: exclude | J30: E4
A31: R0030 | B31: A_both | C31: v1/v2 | D31: 2023 | E31: Evaluation of linear, nonlinear and ensemble machine learning models for landslide susceptibility assessment in southwest China | F31: Geocarto International | G31: 10.1080/10106049.2022.2152493 | H31: 2-s2.0-85143635131 | I31: exclude | J31: E2
A32: R0031 | B32: A_both | C32: v1/v2 | D32: 2025 | E32: A dissimilarity-adaptive cross-validation method for evaluating geospatial machine learning predictions with clustered samples | F32: Ecological Informatics | G32: 10.1016/j.ecoinf.2025.103287 | H32: 2-s2.0-105009502618 | I32: include
A33: R0032 | B33: A_both | C33: v1/v2 | D33: 2019 | E33: Statistical stability and spatial instability in mapping forest tree species by comparing 9 years of satellite image time series | F33: Remote Sensing | G33: 10.3390/rs11212512 | H33: 2-s2.0-85074657977 | I33: include
A34: R0033 | B34: A_both | C34: v1/v2 | D34: 2021 | E34: Importance of spatial autocorrelation in machine learning modeling of polymetallic nodules, model uncertainty and transferability at local scale | F34: Minerals | G34: 10.3390/min11111172 | H34: 2-s2.0-85117621165 | I34: exclude | J34: E4
A35: R0034 | B35: A_both | C35: v1/v2 | D35: 2024 | E35: Deep learning bias correction of GEMS tropospheric NO2: A comparative validation of NO2 from GEMS and TROPOMI using Pandora observations | F35: Environment International | G35: 10.1016/j.envint.2024.108818 | H35: 2-s2.0-85196035166 | I35: exclude | J35: E2
A36: R0035 | B36: A_both | C36: v1/v2 | D36: 2025 | E36: A Comparative Assessment of Regular and Spatial Cross-Validation in Subfield Machine Learning Prediction of Maize Yield from Sentinel-2 Phenology | F36: Eng | G36: 10.3390/eng6100270 | H36: 2-s2.0-105020012052 | I36: include
A37: R0036 | B37: A_both | C37: v1/v2 | D37: 2024 | E37: Toward an Operational Monitoring of Oak Dieback With Multispectral Satellite Time Series: A Case Study in Centre-Val De Loire Region of France | F37: IEEE Journal of Selected Topics in Applied Earth Observations and Remote Sensing | G37: 10.1109/JSTARS.2023.3332420 | H37: 2-s2.0-85177071887 | I37: include
A38: R0037 | B38: A_both | C38: v1/v2 | D38: 2025 | E38: Foundation for unbiased cross-validation of spatio-temporal models for Species Distribution Modeling | F38: Ecological Informatics | G38: 10.1016/j.ecoinf.2025.103521 | H38: 2-s2.0-105022288803 | I38: include
A39: R0038 | B39: A_both | C39: v1/v2 | D39: 2024 | E39: Benchmarking data handling strategies for landslide susceptibility modelingusing random forest workflows | F39: Artificial Intelligence in Geosciences | G39: 10.1016/j.aiig.2024.100093 | H39: 2-s2.0-85206855138 | I39: include
A40: R0039 | B40: A_both | C40: v1/v2 | D40: 2024 | E40: Modelling Europe-wide fine resolution daily ambient temperature for 2003–2020 using machine learning | F40: Science of the Total Environment | G40: 10.1016/j.scitotenv.2024.172454 | H40: 2-s2.0-85190717933 | I40: include
...

Sheet 2_Full_text
A1: record_id | B1: ft_decision | C1: ft_reason | D1: n_rows_extracted | E1: notes | F1: Year | G1: Title | H1: Source title | I1: DOI
A2: R0001 | B2: include | D2: 4 | E2: Random 10-fold vs spatial 44-cluster and buffered LOO; RF AGB central Africa. | F2: 2020 | G2: Spatial validation reveals poor predictive performance of large-scale ecological mapping models | H2: Nature Communications | I2: 10.1038/s41467-020-18321-y
A3: R0002 | B3: include | D3: 4 | E3: Nested random vs k-means spatial repeated 5-fold CV; 4 ML models plus GLM/GAM (not extracted). Preprint. | F3: 2019 | G3: Hyperparameter tuning and performance assessment of statistical and machine-learning algorithms using spatial data | H3: Ecological Modelling | I3: 10.1016/j.ecolmodel.2019.06.002
A4: R0005 | B4: include | D4: 4 | E4: Random vs block (LULC) and leave-cluster-out (LAI) CV; RF. Preprint. | F4: 2019 | G4: Importance of spatial predictor variable selection in machine learning applications – Moving from data reproduction to spatial prediction | H4: Ecological Modelling | I4: 10.1016/j.ecolmodel.2019.108815
A5: R0006 | B5: exclude | C5: E2 | D5: 0 | E5: Virtual-species SDMs; only random split CV vs true performance; no spatial CV. | F5: 2021 | G5: Assessing the reliability of species distribution projections in climate change research | H5: Diversity and Distributions | I5: 10.1111/ddi.13252
A6: R0009 | B6: include | D6: 3 | E6: CNN tree species; random tile split vs site-block hold-out; F1 read from Fig. 3 boxplots. | F6: 2022 | G6: Spatially autocorrelated training and validation samples inflate performance assessment of convolutional neural networks | H6: ISPRS Open Journal of Photogrammetry and Remote Sensing | I6: 10.1016/j.ophoto.2022.100018
A7: R0013 | B7: include | D7: 3 | E7: Global Ksat RF; random vs 5-degree block 5-fold CV, Table 2. | F7: 2021 | G7: Global Prediction of Soil Saturated Hydraulic Conductivity Using Random Forest in a Covariate-Based GeoTransfer Function (CoGTF) Framework | H7: Journal of Advances in Modeling Earth Systems | I7: 10.1029/2020MS002242
A8: R0036 | B8: include | D8: 2 | E8: RF oak dieback; LOO vs 10 km buffered SLOO; values read from Fig. 10. | F8: 2024 | G8: Toward an Operational Monitoring of Oak Dieback With Multispectral Satellite Time Series: A Case Study in Centre-Val De Loire Region of France | H8: IEEE Journal of Selected Topics in Applied Earth Observations and Remote Sensing | I8: 10.1109/JSTARS.2023.3332420
A9: R0037 | B9: exclude | C9: E5 | D9: 0 | E9: Fold-mean CV AUC per scheme not in main text; only CV-test MAE and test AUC. Check supplement S4/GitHub. | F9: 2025 | G9: Foundation for unbiased cross-validation of spatio-temporal models for Species Distribution Modeling | H9: Ecological Informatics | I9: 10.1016/j.ecoinf.2025.103521
A10: R0059 | B10: include | D10: 3 | E10: RF SOC; random repeated 10-fold vs spatial CV (Table 4); spatial CV poorly described. | F10: 2026 | G10: Enhancing digital mapping of soil organic carbon through spatial modeling and validation | H10: Scientific Reports | I10: 10.1038/s41598-026-39496-2
A11: R0093 | B11: include | D11: 2 | E11: RF/GBR delta18O; LOOCV vs 4 longitude blocks; R2 only; n=96. | F11: 2026 | G11: Ensemble machine learning method for δ18O prediction in groundwater | H11: Scientific Reports | I11: 10.1038/s41598-026-57131-y
A12: R0025 | B12: include | D12: 1 | E12: Random 80/20 split vs leave-one-sub-basin-out (9 sub-basins), RF metamodel of drainage fraction. | F12: 2022 | G12: Assessing spatial transferability of a random forest metamodel for predicting drainage fraction | H12: Journal of Hydrology | I12: 10.1016/j.jhydrol.2022.128177
A13: R0063 | B13: include | D13: 6 | E13: Borderline domain (farmer-perceived agricultural vulnerability). Standard vs 50 km spatial block CV, Table 1 macro-F1; accuracy and other block sizes only in supplement. | F13: 2026 | G13: Seasonal agricultural vulnerability in semi-arid Morocco: combining remote sensing and farmer knowledge to inform climate adaptation | H13: Climatic Change | I13: 10.1007/s10584-026-04160-1
A14: R0069 | B14: include | D14: 72 | E14: Random repeated 70/30 vs region-grouped CV for 4 crop yields x 3 models; with/without Year variants. | F14: 2026 | G14: Analyzing meteorological effects on crop yield and yield prediction through machine learning with different data partitioning approaches: A case study from Czech Republic | H14: Journal of Agriculture and Food Research | I14: 10.1016/j.jafr.2026.102662
A15: R0111 | B15: include | D15: 8 | E15: Borderline domain (Fasciola infection risk from drone environmental indices). Stratified 5-fold vs 3 spatial cluster folds, accuracy Table 3. | F15: 2026 | G15: Drone-based geospatial prediction modeling identifies Fasciola hepatica infection risk in the Cusco Highlands of Peru | H15: Infectious Diseases of Poverty | I15: 10.1186/s40249-026-01420-1
A16: R0113 | B16: include | D16: 2 | E16: Random 5-fold vs leave-one-district-out, GB only (Table 4). Article in press; internal inconsistencies noted. | F16: 2026 | G16: Explainable machine learning for climate change attribution and hotspot identification: spatial cross-validation analysis in South Asian Region | H16: Scientific Reports | I16: 10.1038/s41598-026-57382-9
A17: R0122 | B17: exclude | C17: E2 | D17: 0 | E17: Only spatial (block GroupKFold and block-based 70/30 test); no random CV. | F17: 2026 | G17: Predicting surface urban heat island intensity and its drivers using machine learning and spatial XAI for achieving SDG-11 | H17: Computational Urban Science | I17: 10.1007/s43762-026-00291-4
A18: R0136 | B18: include | D18: 1 | E18: Preprint (arXiv) of Meyer & Pebesma 2021 MEE; simulated response; random 10-fold vs leave-cluster-out RMSE from text. Check published version. | F18: 2021 | G18: Predicting into unknown space? Estimating the area of applicability of spatial prediction models | H18: Methods in Ecology and Evolution | I18: 10.1111/2041-210X.13650
A19: R0158 | B19: include | D19: 24 | E19: LOO (h=0, digitised from Fig. 3) vs h-block CV at variogram range (Table 3); pollen-climate calibration, NA and Europe. | F19: 2019 | G19: Machine-learning based reconstructions of primary and secondary climate variables from North American and European fossil pollen data | H19: Scientific Reports | I19: 10.1038/s41598-019-52293-4
A20: R0174 | B20: exclude | C20: E3 | D20: 0 | E20: No ML model and no CV comparison (temporal adjustment of short-term air pollution observations). | F20: 2020 | G20: Spatial modelling of particulate matter air pollution sensor measurements collected by community scientists while cycling, land use regression with spatial cross-validation, and applications of machine learning for data correction | H20: Atmospheric Environment | I20: 10.1016/j.atmosenv.2020.117479
A21: R0200 | B21: include | D21: 8 | E21: 5-fold vs spatial block CV MAE of best algorithm per pigment (Table 4); best-model identity under 5-fold in Suppl. S4. | F21: 2020 | G21: Accuracy of Empirical Satellite Algorithms for Mapping Phytoplankton Diagnostic Pigments in the Open Ocean: A Supervised Learning Perspective | H21: Frontiers in Marine Science | I21: 10.3389/fmars.2020.00599
A22: R0201 | B22: include | D22: 30 | E22: Random 10-fold vs station-grouped 10-fold CV, PCNN-DNN, Table 1 per year (RMSE, MAE; R in notes). | F22: 2023 | G22: A Coupled Deep Learning Model for Estimating Surface NO2 Levels From Remote Sensing Data: 15-Year Study Over the Contiguous United States | H22: Journal of Geophysical Research: Atmospheres | I22: 10.1029/2022JD037010
A23: R0208 | B23: include | D23: 3 | E23: arXiv preprint of IJGIS 2023 paper; RF values digitised from Figs 2 and 4 (Meuse RMSE; Maipo accuracy = 1-error rate). Geostatistical/linear models not extracted. | F23: 2023 | G23: Spatial machine-learning model diagnostics: a model-agnostic distance-based approach | H23: International Journal of Geographical Information Science | I23: 10.1080/13658816.2022.2131789
A24: R0218 | B24: exclude | C24: E2 | D24: 0 | E24: Only spatial block CV (blockCV, 100 km, 13 folds) reported; AUC comparisons are across thinning datasets, not random vs spatial CV. Supplement (Fig. S4) not checked. | F24: 2022 | G24: Large-scale forecasting of Heracleum sosnowskyi habitat suitability under the climate change on publicly available data | H24: Scientific Reports | I24: 10.1038/s41598-022-09953-9
A25: R0232 | B25: include | D25: 16 | E25: Spatial k-means CV vs non-spatial CV, RF land cover (Table 2) and foliar cover (Table 5). | F25: 2022 | G25: Contributions to Satellite-Based Land Cover Classification, Vegetation Quantification and Grassland Monitoring in Central Asian Highlands Using Sentinel-2 and MODIS Data | H25: Frontiers in Environmental Science | I25: 10.3389/fenvs.2022.684589
A26: R0245 | B26: include | D26: 6 | E26: Sea-ice DeepLabV3: benchmark held-out test (random-like, not stated random) vs 2-region spatial CV (Fig. 13 digitised). Borderline random comparator; flagged. | F26: 2025 | G26: Enhancing and Interpreting Deep Learning for Sea Ice Charting using the AutoICE Benchmark | H26: Remote Sensing Applications: Society and Environment | I26: 10.1016/j.rsase.2025.101538
A27: R0270 | B27: include | D27: 6 | E27: RF pasture biomass: 75/25 random split vs leave-location-out; values printed in Fig. 9. | F27: 2020 | G27: Retrieval of hyperspectral information from multispectral data for perennial ryegrass biomass estimation | H27: Sensors (Switzerland) | I27: 10.3390/s20247192
A28: R0408 | B28: include | D28: 6 | E28: Country-level FAOSTAT panel, RF/XGB 10-fold vs 10-block spatial CV (Table 2). Scope borderline; flagged for second reviewer. | F28: 2025 | G28: A machine learning approach to identifying climate change drivers in Africa’s bioenergy sector | H28: Discover Sustainability | I28: 10.1007/s43621-025-01475-4
A29: R0453 | B29: exclude | C29: E2 | D29: 0 | E29: Barn-filter RF evaluated only with spatial block CV (buffers 500-5000 m); farm-type and population RFs only random split. No same model with both. Also borderline E4 (livestock infrastructure). | F29: 2026 | G29: Predicting the spatial distribution and demographics of commercial swine farms in the United States | H29: Preventive Veterinary Medicine | I29: 10.1016/j.prevetmed.2026.106963
A30: R0473 | B30: include | D30: 12 | E30: 4 tree models: random 105/46 test split vs 4-block spatial CV (Table 3, Fig. 3). | F30: 2026 | G30: Interpretable machine learning reveals spatial drivers and regional gradients of soil organic matter across Anhui Province, China | H30: Environmental Earth Sciences | I30: 10.1007/s12665-026-13102-0
A31: R0603 | B31: include | D31: 12 | E31: 4 boosting/RF models, random 80/20 vs 5-fold spatial block CV (Table 3); LR not extracted. | F31: 2026 | G31: Spatially validated assessment of seismic hazard-prone environments in Myanmar using multi-source data and interpretable machine learning | H31: Scientific reports | I31: 10.1038/s41598-026-45557-3
A32: R0672 | B32: exclude | C32: E2 | D32: 0 | E32: Only spatial CV (k-means 5-block GroupKFold) on the training set; the 70/30 hold-out of positive sites is not described as random and is evaluated with the final model, so no matched random CV. RF spatial-CV AUC 0.883 vs hold-out AUC 0.883. Also borderline domain (urban illegal dumping, PU learning). | F32: 2026 | G32: A GeoAI framework for detecting risk zones from illegal dumping sites in Khulna, Bangladesh | H32: PLOS ONE | I32: 10.1371/journal.pone.0345178
A33: R0676 | B33: exclude | C33: E2 | D33: 0 | E33: QC reconciliation 2026-10-12: first decision kept. Global AUC is resubstitution, not random CV: the public notebook (github.com/RelativelyBurberry/wildfire-wuipi) fits on the balanced sample and scores predict_proba on all pixels. Spatial = west/east half hold-out. RF global AUC 0.948 vs spatial AUC 0.547 (Tables 6, 9); not usable as random-vs-spatial comparison. | F33: 2026 | G33: Spatial bias in wildfire ignition models using a wildland urban Interface Pressure Index in the Tamil Nadu and Karnataka Belt | H33: Frontiers in Forests and Global Change | I33: 10.3389/ffgc.2026.1857505
A34: R0715 | B34: exclude | C34: E2 | D34: 0 | E34: In-domain evaluation trains and tests on the same pixels (no random CV); only 4-fold spatial quadrant block holdout. Train vs test-block R2 in Table 4. EarthArXiv preprint of RSE paper (10.1016/j.rse.2026.115610). | F34: 2026 | G34: Calibrated spatial uncertainty for Earth observation foundation models via Matérn-motivated latent stochastic regularization | H34: Remote Sensing of Environment | I34: 10.1016/j.rse.2026.115610
A35: R0722 | B35: exclude | C35: E2 | D35: 0 | E35: Only random 70:30 and 80:20 splits; spatial validation on other rice plots mentioned but not quantified. | F35: 2025 | G35: Spatial Analysis of Ensemble Learning Models for Agricultural Drought Early Warning | H35: Journal of Applied Data Sciences | I35: 10.47738/jads.v7i1.1108
A36: R0757 | B36: include | D36: 16 | E36: RF (+CV predictors, full season): random 70/30 test (dashed lines Fig. 7) vs leave-one-field-out (10 fields); 8 fibre traits x R2/RMSE. LOFO means partly from text, rest digitised from Fig. 7. | F36: 2026 | G36: Geospatializing cotton fiber quality: a step towards on-farm traceability and predictability | H36: Precision Agriculture | I36: 10.1007/s11119-026-10332-x
A37: R0976 | B37: include | D37: 9 | E37: Three GFMs (Prithvi 2.0, Clay, DOFA) x 3 sensors; random 75/10/15 split (Table III) vs leave-one-region-out over 5 regions (Table IV). F1 extracted (mIoU in notes); PlanetScope primary. | F37: 2026 | G37: Assessing Geo-Foundational Models for Flood Inundation Mapping: Benchmarking Models for Sentinel-1, Sentinel-2, and Planetscope | H37: IEEE Journal of Selected Topics in Applied Earth Observations and Remote Sensing | I37: 10.1109/JSTARS.2026.3656855
A38: R0980 | B38: include | D38: 6 | E38: RF digital soil mapping; leave-one-country-out reconstructed from four 3-country donor models (Table 6) vs their 10-fold random CV (Table 4); clay, OC, pH x RMSE/MEC. | F38: 2024 | G38: Evaluating the extrapolation potential of random forest digital soil mapping | H38: Geoderma | I38: 10.1016/j.geoderma.2023.116740
A39: R0986 | B39: include | D39: 8 | E39: Multitask LSTM soil moisture; random 5-fold over sites vs 7-region leave-one-region-out (Table 1b/c). RMSE global (primary) + 7 regional subsets (primary=no); Pearson R in notes. | F39: 2023 | G39: Evaluating a global soil moisture dataset from a multitask model (GSM3 v1.0) with potential applications for crop threats | H39: Geoscientific Model Development | I39: 10.5194/gmd-16-1553-2023
A40: R1001 | B40: exclude | C40: E5 | D40: 0 | E40: GBM (xgboost) with random 5-fold CV vs data-driven spatiotemporal CV (Table 1), but the only metric is the EVA 2021 challenge score (weighted squared exceedance-probability errors), not in the codebook metric list. E.g. dGPD 2896 (random) vs 3215 (spatial) vs 3068 true test score. Usable only if metric list is expanded. | F40: 2023 | G40: Gradient boosting with extreme-value theory for wildfire prediction | H40: Extremes | I40: 10.1007/s10687-022-00454-6
...

Sheet 3_Extraction_raw
A1: record_id | B1: study_id | C1: first_author | D1: year | E1: doi | F1: journal | G1: country | H1: domain | I1: target_variable | J1: task | K1: sampling_design | L1: n_samples | M1: study_area_km2 | N1: model | O1: spatial_cv_type | P1: random_cv_type | Q1: block_or_buffer_size_m | R1: autocorrelation_range_m | S1: n_folds | T1: metric | U1: value_random | V1: value_spatial | W1: sd_random | X1: sd_spatial | Y1: independent_validation | Z1: value_independent | AA1: source_location | AB1: digitised | AC1: open_data | AD1: open_code | AE1: notes | AF1: primary | AG1: variant | AH1: random_cv_alt | AI1: metric_aggregation | AJ1: n_folds_random | AK1: n_folds_spatial | AL1: n_repeats | AM1: block_size_unit | AN1: independent_type | AO1: published_doi
A2: R0001 | B2: S0001 | C2: Ploton | D2: 2020 | E2: 10.1038/s41467-020-18321-y | F2: Nature Communications | G2: Central Africa (Gabon, Cameroon, Congo, CAR, DRC) | H2: vegetation | I2: aboveground forest biomass (1-km pixels) | J2: regression | K2: clustered | L2: 28225 | N2: RF | O2: cluster | P2: random_kfold | Q2: 150000 | R2: 120000 | S2: 10 random / 44 spatial | T2: R2 | U2: 0.53 | V2: 0.14 | Y2: no | AA2: p.4-5 text; Fig. 4 | AB2: no | AC2: yes | AD2: yes | AE2: Hierarchical clustering of coordinates, cluster height 150 km. R2 = squared Pearson r. Inventory plots in logging concessions. RF on coordinates only (RFXY) not extracted. | AF2: yes | AJ2: 10 random / 44 spatial
A3: R0001 | B3: S0001 | C3: Ploton | D3: 2020 | E3: 10.1038/s41467-020-18321-y | F3: Nature Communications | G3: Central Africa (Gabon, Cameroon, Congo, CAR, DRC) | H3: vegetation | I3: aboveground forest biomass (1-km pixels) | J3: regression | K3: clustered | L3: 28225 | N3: RF | O3: cluster | P3: random_kfold | Q3: 150000 | R3: 120000 | S3: 10 random / 44 spatial | T3: RMSE | U3: 56.5 | V3: 77.5 | Y3: no | AA3: p.4-5 text | AB3: no | AC3: yes | AD3: yes | AE3: RMSPE in Mg/ha. Null (intercept-only) model RMSPE = 82 Mg/ha. | AF3: yes | AJ3: 10 random / 44 spatial
A4: R0001 | B4: S0001 | C4: Ploton | D4: 2020 | E4: 10.1038/s41467-020-18321-y | F4: Nature Communications | G4: Central Africa (Gabon, Cameroon, Congo, CAR, DRC) | H4: vegetation | I4: aboveground forest biomass (1-km pixels) | J4: regression | K4: clustered | L4: 28225 | N4: RF | O4: buffer_LOO | P4: LOO | Q4: 150000 | R4: 120000 | S4: LOO (100 test obs x 10 reps) | T4: R2 | U4: 0.50 | V4: 0.03 | Y4: no | AA4: p.5 text; Fig. 5a | AB4: yes | AC4: yes | AD4: yes | AE4: Random = B-LOO with 0 km buffer (text). Spatial = 150 km buffer read from Fig. 5a (approx.). R2 ~0.15 at 50 km. | AF4: yes | AJ4: LOO (100 test obs x 10 reps)
A5: R0001 | B5: S0001 | C5: Ploton | D5: 2020 | E5: 10.1038/s41467-020-18321-y | F5: Nature Communications | G5: Central Africa (Gabon, Cameroon, Congo, CAR, DRC) | H5: vegetation | I5: aboveground forest biomass (1-km pixels) | J5: regression | K5: clustered | L5: 28225 | N5: RF | O5: buffer_LOO | P5: LOO | Q5: 150000 | R5: 120000 | S5: LOO (100 test obs x 10 reps) | T5: RMSE | U5: 58 | V5: 83 | Y5: no | AA5: Fig. 5b | AB5: yes | AC5: yes | AD5: yes | AE5: RMSPE in Mg/ha, both read from Fig. 5b (approx.): 0 km vs 150 km buffer. | AF5: yes | AJ5: LOO (100 test obs x 10 reps)
A6: R0002 | B6: S0002 | C6: Schratz | D6: 2018 | E6: arXiv:1803.11266 | F6: arXiv preprint (later Ecological Modelling 2019) | G6: Spain (Basque Country) | H6: species_distribution | I6: Diplodia sapinea infection of Pinus radiata trees (presence/absence) | J6: classification | K6: unknown | L6: 926 | M6: 7355 | N6: RF | O6: cluster | P6: repeated_kfold | S6: 5 (x100 repetitions) | T6: AUC | U6: 0.912 | V6: 0.699 | Y6: no | AA6: Table 2 | AB6: no | AC6: no | AD6: yes | AE6: k-means coordinate clustering. Matched setups: non-spatial/non-spatial vs spatial/spatial tuning. no tuning: 0.913 vs 0.704. GLM/GAM not extracted. | AF6: yes | AJ6: 5 (x100 repetitions)
A7: R0002 | B7: S0002 | C7: Schratz | D7: 2018 | E7: arXiv:1803.11266 | F7: arXiv preprint (later Ecological Modelling 2019) | G7: Spain (Basque Country) | H7: species_distribution | I7: Diplodia sapinea infection of Pinus radiata trees (presence/absence) | J7: classification | K7: unknown | L7: 926 | M7: 7355 | N7: GBM | O7: cluster | P7: repeated_kfold | S7: 5 (x100 repetitions) | T7: AUC | U7: 0.908 | V7: 0.671 | Y7: no | AA7: Table 2 | AB7: no | AC7: no | AD7: yes | AE7: k-means coordinate clustering. Matched setups: non-spatial/non-spatial vs spatial/spatial tuning. BRT (gbm); no tuning: 0.792 vs 0.583. GLM/GAM not extracted. | AF7: yes | AJ7: 5 (x100 repetitions)
A8: R0002 | B8: S0002 | C8: Schratz | D8: 2018 | E8: arXiv:1803.11266 | F8: arXiv preprint (later Ecological Modelling 2019) | G8: Spain (Basque Country) | H8: species_distribution | I8: Diplodia sapinea infection of Pinus radiata trees (presence/absence) | J8: classification | K8: unknown | L8: 926 | M8: 7355 | N8: SVM | O8: cluster | P8: repeated_kfold | S8: 5 (x100 repetitions) | T8: AUC | U8: 0.878 | V8: 0.650 | Y8: no | AA8: Table 2 | AB8: no | AC8: no | AD8: yes | AE8: k-means coordinate clustering. Matched setups: non-spatial/non-spatial vs spatial/spatial tuning. no tuning: 0.881 vs 0.573. GLM/GAM not extracted. | AF8: yes | AJ8: 5 (x100 repetitions)
A9: R0002 | B9: S0002 | C9: Schratz | D9: 2018 | E9: arXiv:1803.11266 | F9: arXiv preprint (later Ecological Modelling 2019) | G9: Spain (Basque Country) | H9: species_distribution | I9: Diplodia sapinea infection of Pinus radiata trees (presence/absence) | J9: classification | K9: unknown | L9: 926 | M9: 7355 | N9: other | O9: cluster | P9: repeated_kfold | S9: 5 (x100 repetitions) | T9: AUC | U9: 0.872 | V9: 0.624 | Y9: no | AA9: Table 2 | AB9: no | AC9: no | AD9: yes | AE9: k-means coordinate clustering. Matched setups: non-spatial/non-spatial vs spatial/spatial tuning. WKNN (kknn); no tuning: 0.870 vs 0.635. GLM/GAM not extracted. | AF9: yes | AJ9: 5 (x100 repetitions)
A10: R0005 | B10: S0005a | C10: Meyer | D10: 2019 | E10: arXiv:1908.07805 | F10: arXiv preprint (later Ecological Modelling 2019) | G10: Germany (Marburg Open Forest) | H10: land_cover | I10: land use/land cover (10 classes) | J10: classification | K10: clustered | L10: 185000 | M10: 7.5 | N10: RF | O10: block | P10: random_kfold | S10: 20 | T10: accuracy | U10: 0.99 | V10: 0.71 | Y10: no | AA10: Table 2 | AB10: no | AC10: no | AD10: yes | AE10: Model 1 (all 16 predictors incl. lat/lon), by-fold mean. Random reported as >0.99 (lower bound). Global: >0.99 vs 0.68. Spatial FFS model: 0.89 vs 0.71. | AF10: yes | AJ10: 20
A11: R0005 | B11: S0005a | C11: Meyer | D11: 2019 | E11: arXiv:1908.07805 | F11: arXiv preprint (later Ecological Modelling 2019) | G11: Germany (Marburg Open Forest) | H11: land_cover | I11: land use/land cover (10 classes) | J11: classification | K11: clustered | L11: 185000 | M11: 7.5 | N11: RF | O11: block | P11: random_kfold | S11: 20 | T11: kappa | U11: 0.99 | V11: 0.55 | Y11: no | AA11: Table 2 | AB11: no | AC11: no | AD11: yes | AE11: Model 1, by-fold mean. Random reported as >0.99. 20 equal blocks, size not stated (~600 m). Global: >0.99 vs 0.61. Spatial FFS: 0.87 vs 0.56. | AF11: yes | AJ11: 20
A12: R0005 | B12: S0005b | C12: Meyer | D12: 2019 | E12: arXiv:1908.07805 | F12: arXiv preprint (later Ecological Modelling 2019) | G12: Germany (Marburg Open Forest) | H12: vegetation | I12: leaf area index (lidar-derived) | J12: regression | K12: clustered | L12: 824 | M12: 7.5 | N12: RF | O12: leave_location_out | P12: random_kfold | S12: 11 | T12: RMSE | U12: 0.96 | V12: 1.25 | Y12: no | AA12: Table 3 | AB12: no | AC12: no | AD12: yes | AE12: Model 1 (all 15 predictors), by-fold mean; LAI units (m2/m2). Leave-one-cluster-out, 11 clusters of 60 m radius. Global: 0.97 vs 1.75. Spatial FFS: 1.12 vs 1.20. | AF12: yes | AJ12: 11
A13: R0005 | B13: S0005b | C13: Meyer | D13: 2019 | E13: arXiv:1908.07805 | F13: arXiv preprint (later Ecological Modelling 2019) | G13: Germany (Marburg Open Forest) | H13: vegetation | I13: leaf area index (lidar-derived) | J13: regression | K13: clustered | L13: 824 | M13: 7.5 | N13: RF | O13: leave_location_out | P13: random_kfold | S13: 11 | T13: R2 | U13: 0.86 | V13: 0.58 | Y13: no | AA13: Table 3 | AB13: no | AC13: no | AD13: yes | AE13: Model 1, GLOBAL R2 (authors say by-fold R2 unreliable: 0.87 vs 0.07). Spatial FFS global: 0.81 vs 0.63. | AF13: yes | AJ13: 11
A14: R0009 | B14: S0009 | C14: Kattenborn | D14: 2022 | E14: 10.1016/j.ophoto.2022.100018 | F14: ISPRS Open Journal of Photogrammetry and Remote Sensing | G14: Germany (Black Forest) | H14: vegetation | I14: tree species (semantic segmentation of UAV RGB tiles) | J14: classification | K14: clustered | L14: 10 training sites (~1500 tiles each); 7 test sites | M14: 3600 | N14: CNN | O14: leave_location_out | P14: random_split | Q14: 100 | S14: 5 repetitions | T14: F1 | U14: 0.71 | V14: 0.47 | Y14: no | AA14: Fig. 3; p.4 text | AB14: yes | AC14: yes | AD14: yes | AE14: U-net, no augmentation; boxplot medians read from Fig. 3. Random = 80/20 tiles within training sites; spatial = 7 unseen 100x100 m sites. Text optimism 27.9%. SAC flattens ~20 m. | AF14: yes | AJ14: 5 repetitions
A15: R0009 | B15: S0009 | C15: Kattenborn | D15: 2022 | E15: 10.1016/j.ophoto.2022.100018 | F15: ISPRS Open Journal of Photogrammetry and Remote Sensing | G15: Germany (Black Forest) | H15: vegetation | I15: tree species (semantic segmentation of UAV RGB tiles) | J15: classification | K15: clustered | L15: 25 training sites (~1500 tiles each); 7 test sites | M15: 3600 | N15: CNN | O15: leave_location_out | P15: random_split | Q15: 100 | S15: 5 repetitions | T15: F1 | U15: 0.74 | V15: 0.59 | Y15: no | AA15: Fig. 3; p.4 text | AB15: yes | AC15: yes | AD15: yes | AE15: U-net, no augmentation; boxplot medians read from Fig. 3. Random = 80/20 tiles within training sites; spatial = 7 unseen 100x100 m sites. Text optimism 17.7%. SAC flattens ~20 m. | AF15: yes | AJ15: 5 repetitions
A16: R0009 | B16: S0009 | C16: Kattenborn | D16: 2022 | E16: 10.1016/j.ophoto.2022.100018 | F16: ISPRS Open Journal of Photogrammetry and Remote Sensing | G16: Germany (Black Forest) | H16: vegetation | I16: tree species (semantic segmentation of UAV RGB tiles) | J16: classification | K16: clustered | L16: 40 training sites (~1500 tiles each); 7 test sites | M16: 3600 | N16: CNN | O16: leave_location_out | P16: random_split | Q16: 100 | S16: 5 repetitions | T16: F1 | U16: 0.76 | V16: 0.65 | Y16: no | AA16: Fig. 3; p.4 text | AB16: yes | AC16: yes | AD16: yes | AE16: U-net, no augmentation; boxplot medians read from Fig. 3. Random = 80/20 tiles within training sites; spatial = 7 unseen 100x100 m sites. Text optimism 14.6%. SAC flattens ~20 m. | AF16: yes | AJ16: 5 repetitions
A17: R0013 | B17: S0013 | C17: Gupta | D17: 2021 | E17: 10.1029/2020MS002242 | F17: Journal of Advances in Modeling Earth Systems | G17: Global | H17: soil | I17: log10 saturated hydraulic conductivity (Ksat) | J17: regression | K17: clustered | L17: 6814 | N17: RF | O17: block | P17: repeated_kfold | Q17: 555000 | S17: 5 (x3 repetitions) | T17: RMSE | U17: 0.72 | V17: 1.18 | Y17: no | AA17: Table 2 | AB17: no | AC17: yes | AD17: yes | AE17: Full CoGTF model (28 covariates, mtry 6). 5x5 degree blocks (~555 km at equator). RMSE in log10(cm/day). Soil-only and environment-only subsets also in Table 2. | AF17: yes | AJ17: 5 (x3 repetitions)
A18: R0013 | B18: S0013 | C18: Gupta | D18: 2021 | E18: 10.1029/2020MS002242 | F18: Journal of Advances in Modeling Earth Systems | G18: Global | H18: soil | I18: log10 saturated hydraulic conductivity (Ksat) | J18: regression | K18: clustered | L18: 6814 | N18: RF | O18: block | P18: repeated_kfold | Q18: 555000 | S18: 5 (x3 repetitions) | T18: R2 | U18: 0.66 | V18: 0.10 | Y18: no | AA18: Table 2 | AB18: no | AC18: yes | AD18: yes | AE18: Full CoGTF model (28 covariates, mtry 6). 5x5 degree blocks (~555 km at equator). RMSE in log10(cm/day). Soil-only and environment-only subsets also in Table 2. | AF18: yes | AJ18: 5 (x3 repetitions)
A19: R0013 | B19: S0013 | C19: Gupta | D19: 2021 | E19: 10.1029/2020MS002242 | F19: Journal of Advances in Modeling Earth Systems | G19: Global | H19: soil | I19: log10 saturated hydraulic conductivity (Ksat) | J19: regression | K19: clustered | L19: 6814 | N19: RF | O19: block | P19: repeated_kfold | Q19: 555000 | S19: 5 (x3 repetitions) | T19: CCC | U19: 0.79 | V19: 0.16 | Y19: no | AA19: Table 2 | AB19: no | AC19: yes | AD19: yes | AE19: Full CoGTF model (28 covariates, mtry 6). 5x5 degree blocks (~555 km at equator). RMSE in log10(cm/day). Soil-only and environment-only subsets also in Table 2. | AF19: yes | AJ19: 5 (x3 repetitions)
A20: R0036 | B20: S0036 | C20: Mouret | D20: 2023 | E20: 10.1109/JSTARS.2023.3332420 | F20: IEEE Journal of Selected Topics in Applied Earth Observations and Remote Sensing | G20: France (Centre-Val de Loire) | H20: vegetation | I20: oak dieback status (healthy vs declining plots) | J20: classification | K20: clustered | L20: 2700 | M20: 110000 | N20: RF | O20: buffer_LOO | P20: LOO | Q20: 10000 | S20: LOO (300 reps per year) | T20: balanced_accuracy | U20: 0.745 | V20: 0.68 | Y20: no | AA20: Fig. 10 | AB20: yes | AC20: no | AD20: no | AE20: Raw references, 2 classes, mean all years, both read from Fig. 10. Plot-level LOO, 10 km buffer (20 km similar). Text: BA and OA drop ~5%. | AF20: yes | AJ20: LOO (300 reps per year)
A21: R0036 | B21: S0036 | C21: Mouret | D21: 2023 | E21: 10.1109/JSTARS.2023.3332420 | F21: IEEE Journal of Selected Topics in Applied Earth Observations and Remote Sensing | G21: France (Centre-Val de Loire) | H21: vegetation | I21: oak dieback status (healthy vs declining plots) | J21: classification | K21: clustered | L21: 2700 | M21: 110000 | N21: RF | O21: buffer_LOO | P21: repeated_kfold | Q21: 10000 | S21: 5 (x10 repetitions) | T21: balanced_accuracy | U21: 0.78 | V21: 0.73 | Y21: no | AA21: Table IV; Fig. 10 | AB21: yes | AC21: no | AD21: no | AE21: Expanded references + SMOTE. Random = stratified plot-grouped 5-fold x10 (Table IV, not digitised). Spatial = SLOOCV read from Fig. 10. Different random scheme. | AF21: yes | AJ21: 5 (x10 repetitions)
